File: Figure_codes/Fig_S14/au.txt.vms
VAMAS Surface Chemical Analysis Standard Data Transfer Format 1988 May 4
Not Specified
Not Specified
Not Specified
Not Specified
3
Casa Info Follows CasaXPS Version 2.3.23PR1.0
0
SourceAnalyserAngle: Not Specified
NORM
REGULAR
0
1
Data Set
d
0
0
0
0
1
au.txt
au.txt
0
0
0
0
0
0
0
9
Casa Info Follows
0
0
1
CASA region (*Survey*) (*Shirley*) 971.8 981.4 1 2 0 0 0 -450 0 0 (*NoTag*) 0 0 0
2
CASA comp (*Survey*) (*GL(95)*) Area 1232352.9 1e-020 61733358 -1 1 MFWHM 0.54614463 0.12 3 -1 1 Position 974.83475 971.8 981.4 -1 1 RSF 1 MASS 0 INDEX -1 (*NoTag*) CONST (**) UNCORRECTEDRSF 0
CASA comp (*Survey*) (*GL(95)*) Area 940606.2 1e-020 61733358 -1 1 MFWHM 0.55426453 0.12 3 -1 1 Position 978.51132 971.8 981.4 -1 1 RSF 1 MASS 0 INDEX -1 (*NoTag*) CONST (**) UNCORRECTEDRSF 0

XPS
0
Al
1486.6
1e+037
1e+037
1e+037
1e+037
1e+037
FAT
1e+037
1e+037
1e+037
1e+037
1e+037
1e+037
1e+037
1e+037
Survey

-1
Kinetic Energy
d
951.62
0.02
1
Intensity
d
pulse counting
1
1
1e+037
1e+037
1e+037
1e+037
1
PROPAGATION_CONVERGED
d
1
0
20815
20764.9
20749
20605.6
21336.9
21014.1
21073
21062.5
21155.3
21140
21975.5
22379.7
21954.4
21669.4
22134.2
21988.6
21434.2
21451.5
21341.5
21418.6
21376
21597.1
21284.1
21067.9
22322.2
21944.6
22163
22292.8
22353.7
22541.4
23178.8
22954.2
23085.1
22527.1
22659.4
22363.6
21892.1
22817.8
22369.3
21717.1
21739.2
22909.1
22606.9
22617.3
22624.4
21791.4
22325.9
22766.2
22987.1
22550.1
21858.9
21885.5
21902.7
21801.2
21843.5
21107.1
21809
21423.6
21600
22209.5
21321.7
21650
22193
22088.6
21789.9
21411
21551.9
22186.5
22243.2
22196.2
22155.5
21519.5
21633
21834.1
21781.3
21124.5
21751.4
21509.7
21367
21107.7
21892.4
21921.8
21740.9
22129.7
22427.6
21599.2
21237.5
21526.6
21323.3
21548.7
21857.2
21525.1
21101.1
20682.5
21806.7
21779.2
21296.3
21242
21473.9
21520.3
21319.1
21704
21467.7
21677.3
22307.7
22253.5
21605
22219.1
22043.5
21701.7
21006.6
21529.8
21665.8
21769.2
22070
22478.2
23267.9
22835
22763.8
22606.4
22768.8
23374.9
22853.6
22811.3
22754.6
23444.3
23267.6
22878.8
22847.7
23073.7
23783.1
24505
23032.5
23284.7
24105.7
23971.9
24193
23817.8
24058.2
24500
24745.9
23948.6
25214
25364.1
25183.9
25994
26697.2
27255.3
26797.7
26822.8
26974
27803.6
28897.3
29808.5
30549
31912
31724.9
32680.2
33657.5
34191.5
34251.1
36191.5
38483.6
40094.8
41533.5
42973.6
46077
48287.1
50206.4
53686.3
56578.1
59387.9
61162.6
65880.3
69326.7
70897.3
76156.2
80334.6
82273
86294
89198.6
91169.9
96669.3
100791
102131
105291
108625
112050
113542
116614
118554
120543
122186
120444
121501
121645
122570
123919
122928
122626
123922
123368
122506
121967
122266
122637
120942
120755
120477
119613
119249
120315
121001
119865
118665
117837
117619
116844
116858
114989
113487
113635
112559
112000
111014
110078
109047
108868
106618
105829
106340
104786
102112
102758
100803
97487.1
96877.5
95612.3
93229.8
91246.9
90451.6
88988.1
89527.5
86347.6
84872.4
83687
83020.5
82176.1
80208.4
79510.2
77245.4
77115.3
76264.9
76169.9
74267.2
73269.7
73854.4
72031.6
69191.8
68739.2
68525.4
69108
66540.6
65907.2
66440
64596.6
64382.3
65672.8
64536.5
63109.8
61216.2
60878.5
59529.2
59526
59427.6
58523.5
58275.4
57224.4
57467
56329.6
56340.8
54893
54972.4
55038.5
54032.3
53286.9
53722.8
54151.5
53922.5
54215.1
52976.3
53012.7
50889
51219.7
50871.2
51091.8
51044.2
50910.1
50535.1
49814.9
49665.5
49153.9
49884.2
50270.9
50792.5
49399.4
50100.6
48640.5
48421
48968
49663.7
48425.6
48573.6
48276.6
48670.4
49313.4
48147
47752
46962.3
47510.4
48312.2
48998.9
47324.1
47410
47607.9
46547.3
46957.7
46793.9
46747.8
47042.7
46406.2
45556.2
45849.8
45478.4
46396.8
44894.7
44383.6
45668.9
44394.2
44657.8
45414.9
44456.7
43913.7
43943.4
44657.5
44972.7
44970.8
45086.7
43789.6
43894.5
43224.5
44406.2
43747.6
43149.7
44377.8
43796.4
43861.8
43192.3
43463.8
43490.1
43513.4
43122.8
43065.2
42512.8
43108.6
42033
43095.1
43647.8
43329.2
43727.4
43534.3
42166.4
42089
41765.8
41917.1
41673.9
40764
40763.6
41752
43432.6
43450.2
42548.5
41808
42807.8
42740.1
41277.7
42077.6
43135.2
43102.7
43236.5
42026.2
42434.9
42797.5
42235.9
43170.2
43054.5
42743.4
43975.2
43349.2
42667.7
42115.3
44327.9
42836.2
43127.5
43124.5
42793.2
43188.1
42966.7
43685
44269.3
44275.6
42994.4
41855.7
42589.5
42931.9
44669
43874
43938.4
43949.8
43654.1
43528.9
43156.7
44450.6
44529.6
44446
45396
45359.1
45265
44896.9
45022
44475.8
45878.1
45375.3
46487.4
45033.4
45259.1
44898.8
45332.4
46746.3
46765.6
46461.8
46176.8
45827.1
47225.6
47093.9
46752.7
47194.2
47067
46559.1
47118.4
47677.8
47943.6
47942.6
48047.8
47174.7
47745.9
47689.9
47957.6
48551
46690.5
45604.4
47581.4
47599.4
47166.8
48346.8
47643.5
48435.8
46825.5
47007.4
47003.1
47937.9
48009.5
46844.8
46995.1
47350.5
47788.1
48232.8
47279.3
47750.6
47106.5
46735.9
48779.8
48839.2
48984.8
48530.1
48163.9
47609.1
47975.1
48402.9
47505
48780
48363.4
47940.4
48262.5
47848.6
47897
48106.2
48086.4
48865.8
47636.3
62634.2
62396.4
62398.1
64320
64203.9
63578.7
64140.7
64748.1
64110.7
65173.8
66328.5
66803.1
66142.3
67298.3
66046.6
67635.6
69409.6
68510
69633
69861.9
70720.7
72128.6
71508.4
73150.9
73663.5
73835.2
74513.4
75145
75090.7
76277.2
76960.1
79388.4
79534.2
81334.8
82154.7
83691
85280.1
85836.3
87296
88781.5
89059.7
90806.6
92348.3
93477.7
96148.8
97032.6
99787.6
102163
104280
107860
111693
115866
119039
125464
129274
133741
139439
149345
160501
171961
183228
199542
219905
243482
272999
309233
355350
412389
480987
557054
647845
740148
839572
944713
1.05171e+006
1.16075e+006
1.27058e+006
1.39783e+006
1.53023e+006
1.66231e+006
1.76265e+006
1.81116e+006
1.78238e+006
1.68262e+006
1.52944e+006
1.34854e+006
1.15878e+006
999751
864186
748053
651252
572672
512449
460234
414206
379102
346649
320377
298936
279953
262788
247538
236304
226242
219255
212240
205445
199232
191671
189829
183025
179637
175907
173584
173467
173186
169181
168048
164692
163185
162619
162175
161262
162076
161789
162961
161974
161975
161225
161072
163013
166393
166629
166336
166151
168884
172140
174472
176535
180630
182173
185364
189431
190717
194028
197537
202041
208953
214663
217291
225466
233278
243355
258270
275095
292323
315894
341639
377936
421085
470565
530894
599276
676218
749598
826552
912333
989790
1.07318e+006
1.1694e+006
1.27011e+006
1.35677e+006
1.42838e+006
1.45946e+006
1.43443e+006
1.3588e+006
1.24647e+006
1.109e+006
979503
861811
757557
669244
598045
539857
492819
453210
421994
390941
369254
347955
330468
315150
301778
291130
281457
272515
265060
256653
252965
247232
244258
239130
235932
232674
231735
229246
224955
224180
222147
222644
218000
215459
214354
214991
213742
212297
211758
209922
211216
211562
208587
209031
211634
213049
211806
212288
210000
208739
211046
211695
213435
212956
213766
213543
212537
213660
211382
212508
215114
215131
212605
211833
214691
214171
213517
214733
214014
214524
214841
214399
214672
end of experiment