File: Figure_codes/Fig_S14/mn3d.txt.vms
VAMAS Surface Chemical Analysis Standard Data Transfer Format 1988 May 4
Not Specified
Not Specified
Not Specified
Not Specified
3
Casa Info Follows CasaXPS Version 2.3.23PR1.0
0
SourceAnalyserAngle: Not Specified
NORM
REGULAR
0
1
Data Set
d
0
0
0
0
1
mn3d.txt
mn3d.txt
0
0
0
0
0
0
0
20
Casa Info Follows
0
0
1
CASA region (*Survey*) (*Shirley*) 1429.6 1443.6 1 2 0 0 0 -450 0 0 (*NoTag*) 0 0 0
13
CASA comp (*MnIV*) (*GL(30)*) Area 53496.466 1e-020 3575800.8 -1 1 MFWHM 1.6024871 1 2 -1 1 Position 1437.0779 1436.66 1437.26 -1 1 RSF 1 MASS 0 INDEX -1 (*NoTag*) CONST (**) UNCORRECTEDRSF 0
CASA comp (*MnIV-2*) (*GL(30)*) Area 13802.088 1e-020 3575800.8 0 0.258 MFWHM 1.6024871 0.548 13.7 0 1 Position 1435.7279 0 0 0 -1.35 RSF 1 MASS 0 INDEX -1 (*NoTag*) CONST (**) UNCORRECTEDRSF 0
CASA comp (*MnIV-3*) (*GL(30)*) Area 5082.1643 1e-020 3575800.8 0 0.095 MFWHM 1.6024871 0.548 13.7 0 1 Position 1434.3379 0 0 0 -2.74 RSF 1 MASS 0 INDEX -1 (*NoTag*) CONST (**) UNCORRECTEDRSF 0
CASA comp (*MnIV-4*) (*GL(30)*) Area 2781.8162 1e-020 3575800.8 0 0.052 MFWHM 1.6024871 0.548 13.7 0 1 Position 1432.9379 0 0 0 -4.14 RSF 1 MASS 0 INDEX -1 (*NoTag*) CONST (**) UNCORRECTEDRSF 0
CASA comp (*MnIV-5*) (*GL(30)*) Area 534.96466 1e-020 3575800.8 0 0.01 MFWHM 1.6024871 0.548 13.7 0 1 Position 1431.4579 0 0 0 -5.62 RSF 1 MASS 0 INDEX -1 (*NoTag*) CONST (**) UNCORRECTEDRSF 0
CASA comp (*MnIII*) (*GL(30)*) Area 119609.92 1e-020 3575800.8 -1 1 MFWHM 1.4451229 0.548 13.7 0 0.9018 Position 1438.2279 0 0 0 1.15 RSF 1 MASS 0 INDEX -1 (*NoTag*) CONST (**) UNCORRECTEDRSF 0
CASA comp (*MnIII-2*) (*GL(30)*) Area 50953.824 1e-020 3575800.8 5 0.426 MFWHM 1.445187 0.548 13.7 0 0.90184 Position 1437.0979 0 0 0 0.02 RSF 1 MASS 0 INDEX -1 (*NoTag*) CONST (**) UNCORRECTEDRSF 0
CASA comp (*MnIII-3*) (*GL(30)*) Area 27869.11 1e-020 3575800.8 5 0.233 MFWHM 1.4451229 0.548 13.7 0 0.9018 Position 1435.9079 0 0 0 -1.17 RSF 1 MASS 0 INDEX -1 (*NoTag*) CONST (**) UNCORRECTEDRSF 0
CASA comp (*MnIII-4*) (*GL(30)*) Area 11602.162 1e-020 3575800.8 5 0.097 MFWHM 1.4451229 0.548 13.7 0 0.9018 Position 1434.4979 0 0 0 -2.58 RSF 1 MASS 0 INDEX -1 (*NoTag*) CONST (**) UNCORRECTEDRSF 0
CASA comp (*MnIII-5*) (*GL(30)*) Area 119.60992 1e-020 3575800.8 5 0.001 MFWHM 1.2387225 0.548 13.7 0 0.773 Position 1430.4479 0 0 0 -6.63 RSF 1 MASS 0 INDEX -1 (*NoTag*) CONST (**) UNCORRECTEDRSF 0
CASA comp (*MnII*) (*GL(30)*) Area 4569.554 0 100000 -1 1 MFWHM 1.4451229 0 2 0 0.9018 Position 1439.5579 0 0 0 2.48 RSF 1 MASS 0 INDEX -1 (*NoTag*) CONST (**) UNCORRECTEDRSF 0
CASA comp (*MnII-1*) (*GL(30)*) Area 1471.3964 1e-020 3575800.8 10 0.322 MFWHM 1.6437116 0.548 13.7 0 1.0257253 Position 1438.8579 0 0 0 1.78 RSF 1 MASS 0 INDEX -1 (*NoTag*) CONST (**) UNCORRECTEDRSF 0
CASA comp (*MnII-2*) (*GL(30)*) Area 578.25878 1e-020 3575800.8 10 0.126546 MFWHM 3.5138489 0.548 13.7 0 2.192747 Position 1437.4279 0 0 0 0.35 RSF 1 MASS 0 INDEX -1 (*NoTag*) CONST (**) UNCORRECTEDRSF 0

XPS
0
Al
1486.6
1e+037
1e+037
1e+037
1e+037
1e+037
FAT
1e+037
1e+037
1e+037
1e+037
1e+037
1e+037
1e+037
1e+037
Survey

-1
Kinetic Energy
d
1415.8747
0.02
1
Intensity
d
pulse counting
1
1
1e+037
1e+037
1e+037
1e+037
1
PROPAGATION_CONVERGED
d
1
0
50424
49878.9
50275.3
50527.7
49778.5
50147.7
50446.2
50116.8
50158.4
50834.8
50269.2
50048
50851.6
50086.6
50412.7
50699.7
50595.9
50231.9
49200.6
49685
49895.3
49365.4
50030.4
49200.4
49699
50782.4
50999.8
49909.6
49413.6
50301.1
49384.6
50465.6
51246.1
50120.4
50080.1
49274.4
50150.6
50028.9
52025.2
50577.7
50512.7
49757.4
50120.9
51270.2
50593.3
51469
49431.7
49608.8
49920.4
50107.6
50548.4
51070.9
50580.9
50274.9
50005
49848
49844.8
49140
50556.2
50799.2
49629
50828.2
50743.6
50637.6
50409
51225.3
50582.1
50352.8
50360.7
50647.5
49907.2
50110.3
49610
49439.7
50257
48919
50210.9
49889.8
48909.6
49898
49433.2
51110.3
50190.3
50180
50000.7
49311.4
50418.3
51403.6
50545.9
50449.2
50091.8
50452.2
50875.2
51123.9
51720.4
50927.1
50759.3
50568.5
51292.9
50377.9
50503.5
50885.7
49532.6
49591.3
50403.7
50853.1
49646.4
50214.2
50548.8
50453.8
50583.6
49966.7
50307.7
50840
49969.7
49452.6
50881.8
50073.3
49766.4
49559.2
49870.9
51081
51704.8
50780.5
50778.9
51498.7
50306.3
49767.9
50726.6
51597.8
50620.7
50681.9
50719.5
50491.8
50414.4
51919.8
51060
51162
51400.4
50777.6
50731.5
50724.3
51054.4
51766.6
50363
51253.7
50947.4
50761
51503.6
51262
49958.9
51342.8
51050.9
50233.3
50317.7
50144.2
50894.2
50864.9
50653.8
50751.9
51212
50780.9
50807.1
50119.8
50359.3
49336.7
49313.1
50264.5
49568.9
49347.6
50175.6
50352.7
50376.6
50192.8
50500.9
49664.9
51480
50360.5
49925.9
49008.3
50260.6
49978
50352.5
50262.5
50479.6
49644.9
49730.8
49623.4
50879.2
50393.2
49021.1
49281
49540.1
49434.4
48930.6
49698.9
49556.4
50051.8
49545.4
49542.2
49548.6
49931.2
49392.5
49659.8
50035.6
49447.7
49237.5
49648.3
48933.8
49190.7
49780.4
48841.4
48739.8
50462.4
48867.4
48816.9
48731.4
48786.6
49459.8
49451.8
49121.1
50221.2
50215.3
48538.5
49282.2
49677.6
49251.1
49328.3
48399.8
48688.5
49528.7
49403.4
48794.4
49501.7
49084.2
48922.5
48987
48489.2
49460.8
48622.1
47433.4
47681.9
47790.8
48287.8
48405.2
48677.8
48054.3
49020.3
49524.9
47861.7
47944.8
47636.3
48865.8
48086.4
48106.2
47897
47848.6
48262.5
47940.4
48363.4
48780
47505
48402.9
47975.1
47609.1
48163.9
48530.1
48984.8
48839.2
48779.8
46735.9
47106.5
47750.6
47279.3
48232.8
47788.1
47350.5
46995.1
46844.8
48009.5
47937.9
47003.1
47007.4
46825.5
48435.8
47643.5
48346.8
47166.8
47599.4
47581.4
45604.4
46690.5
48551
47957.6
47689.9
47745.9
47174.7
48047.8
47942.6
47943.6
47677.8
47118.4
46559.1
47067
47194.2
46752.7
47093.9
47225.6
45827.1
46176.8
46461.8
46765.6
46746.3
45332.4
44898.8
45259.1
45033.4
46487.4
45375.3
45878.1
44475.8
45022
44896.9
45265
45359.1
45396
44446
44529.6
44450.6
43156.7
43528.9
43654.1
43949.8
43938.4
43874
44669
42931.9
42589.5
41855.7
42994.4
44275.6
44269.3
43685
42966.7
43188.1
42793.2
43124.5
43127.5
42836.2
44327.9
42115.3
42667.7
43349.2
43975.2
42743.4
43054.5
43170.2
42235.9
42797.5
42434.9
42026.2
43236.5
43102.7
43135.2
42077.6
41277.7
42740.1
42807.8
41808
42548.5
43450.2
43432.6
41752
40763.6
40764
41673.9
41917.1
41765.8
42089
42166.4
43534.3
43727.4
43329.2
43647.8
43095.1
42033
43108.6
42512.8
43065.2
43122.8
43513.4
43490.1
43463.8
43192.3
43861.8
43796.4
44377.8
43149.7
43747.6
44406.2
43224.5
43894.5
43789.6
45086.7
44970.8
44972.7
44657.5
43943.4
43913.7
44456.7
45414.9
44657.8
44394.2
45668.9
44383.6
44894.7
46396.8
45478.4
45849.8
45556.2
46406.2
47042.7
46747.8
46793.9
46957.7
46547.3
47607.9
47410
47324.1
48998.9
48312.2
47510.4
46962.3
47752
48147
49313.4
48670.4
48276.6
48573.6
48425.6
49663.7
48968
48421
48640.5
50100.6
49399.4
50792.5
50270.9
49884.2
49153.9
49665.5
49814.9
50535.1
50910.1
51044.2
51091.8
50871.2
51219.7
50889
53012.7
52976.3
54215.1
53922.5
54151.5
53722.8
53286.9
54032.3
55038.5
54972.4
54893
56340.8
56329.6
57467
57224.4
58275.4
58523.5
59427.6
59526
59529.2
60878.5
61216.2
63109.8
64536.5
65672.8
64382.3
64596.6
66440
65907.2
66540.6
69108
68525.4
68739.2
69191.8
72031.6
73854.4
73269.7
74267.2
76169.9
76264.9
77115.3
77245.4
79510.2
80208.4
82176.1
83020.5
83687
84872.4
86347.6
89527.5
88988.1
90451.6
91246.9
93229.8
95612.3
96877.5
97487.1
100803
102758
102112
104786
106340
105829
106618
108868
109047
110078
111014
112000
112559
113635
113487
114989
116858
116844
117619
117837
118665
119865
121001
120315
119249
119613
120477
120755
120942
122637
122266
121967
122506
123368
123922
122626
122928
123919
122570
121645
121501
120444
122186
120543
118554
116614
113542
112050
108625
105291
102131
100791
96669.3
91169.9
89198.6
86294
82273
80334.6
76156.2
70897.3
69326.7
65880.3
61162.6
59387.9
56578.1
53686.3
50206.4
48287.1
46077
42973.6
41533.5
40094.8
38483.6
36191.5
34251.1
34191.5
33657.5
32680.2
31724.9
31912
30549
29808.5
28897.3
27803.6
26974
26822.8
26797.7
27255.3
26697.2
25994
25183.9
25364.1
25214
23948.6
24745.9
24500
24058.2
23817.8
24193
23971.9
24105.7
23284.7
23032.5
24505
23783.1
23073.7
22847.7
22878.8
23267.6
23444.3
22754.6
22811.3
22853.6
23374.9
22768.8
22606.4
22763.8
22835
23267.9
22478.2
22070
21769.2
21665.8
21529.8
21006.6
21701.7
22043.5
22219.1
21605
22253.5
22307.7
21677.3
21467.7
21704
21319.1
21520.3
21473.9
21242
21296.3
21779.2
21806.7
20682.5
21101.1
21525.1
21857.2
21548.7
21323.3
21526.6
21237.5
21599.2
22427.6
22129.7
21740.9
21921.8
21892.4
21107.7
21367
21509.7
21751.4
21124.5
21781.3
21834.1
21633
21519.5
22155.5
22196.2
22243.2
22186.5
21551.9
21411
21789.9
22088.6
22193
21650
21321.7
22209.5
21600
21423.6
21809
21107.1
21843.5
21801.2
21902.7
21885.5
21858.9
22550.1
22987.1
22766.2
22325.9
21791.4
22624.4
22617.3
22606.9
22909.1
21739.2
21717.1
22369.3
22817.8
21892.1
22363.6
22659.4
22527.1
23085.1
22954.2
23178.8
22541.4
22353.7
22292.8
22163
21944.6
22322.2
21067.9
21284.1
21597.1
21376
21418.6
21341.5
21451.5
21434.2
21988.6
22134.2
21669.4
21954.4
22379.7
21975.5
21140
21155.3
21062.5
21073
21014.1
21336.9
20605.6
20749
20764.9
20815
end of experiment